Workbook

Sheet IVP amount sanctioned
A1: S.NO | B1: NAME | C1: Grant | D1: phone no. | E1: TEAM ID | F1: pitch deck file | G1: Linkedin | H1: colege linkedin
A2: 1 | B2: Aathavan valanarasu | C2: IVP Selected | D2: 9342049639 | E2: SC-rea6ge | F2: https://drive.google.com/file/d/1icj55HRkpEE6D2YhMiuNvMZMm4qS83lU/view?usp=sharing | G2: https://www.linkedin.com/in/aathavanvalan1/overlay/about-this-profile/?lipi=urn%3Ali%3Apage%3Ad_flagship3_profile_view_base%3BriTF2OrHS4OJ7A6z6xWIuQ%3D%3D | H2: https://www.linkedin.com/school/st.-joseph%27s-college-of-engineering/
A3: 2 | B3: DEEPIKA | C3: IVP Selected | D3: 7395956159 | E3: SC-qtithv | F3: https://drive.google.com/file/d/1OUSJwH2xDGJqMtzE109n35wkSSxf7pE8/view?usp=sharing | G3: https://www.linkedin.com/in/deepika-harigovindan-8974a7315/ | H3: https://www.linkedin.com/school/sri-sairam-homoeopathy-medical-college-inst.-code---209-chennai/about/
A4: 3 | B4: vijaykrishna | C4: IVP Selected | D4: 7305499740 | E4: SC-9e48xs | F4: https://docs.google.com/presentation/d/1RcoSCW7AzUCA6qeqWWS2U1sE5cu9pSk6/edit?usp=sharing&ouid=104277249549708518105&rtpof=true&sd=true | G4: https://www.linkedin.com/in/vijay-krishna-s/ | H4: https://www.linkedin.com/school/college-of-engineering-guindy/posts/?feedView=all
A5: 4 | B5: prempradeep S | C5: IVP Selected | D5: 7708365986 | E5: SC-b4jkfxa | F5: https://drive.google.com/file/d/1VorSWnUlyM-hZbEwKD3-ydU3amct_rNZ/view?usp=sharing | G5: https://www.linkedin.com/in/prem-pradeep-s | H5: https://www.linkedin.com/school/r.m.k-engineering-college/
A6: 5 | B6: S varshaa | C6: IVP Selected | D6: 9952048318 | E6: SC-ywojqq | F6: https://docs.google.com/presentation/d/1r_uJDDSgeSqdewnxUdc17ddlmhNFHjj7/edit?usp=sharing&ouid=104277249549708518105&rtpof=true&sd=true | G6: https://www.linkedin.com/in/varshaaselva/?utm_source=share&utm_campaign=share_via&utm_content=profile&utm_medium=ios_app | H6: https://www.linkedin.com/school/r.m.k-engineering-college/
A7: 6 | B7: purushothaman J | C7: IVP Selected | D7: 9176435615 | E7: SC-aodnso | F7: https://docs.google.com/presentation/d/1Jqm6_fP9FgL0YIqrGdUb-tYgGnQ5StAv/edit?usp=sharing&ouid=104277249549708518105&rtpof=true&sd=true | G7: https://www.linkedin.com/in/purushothaman-jayavel-19b121286?utm_source=share&utm_campaign=share_via&utm_content=profile&utm_medium=android_app | H7: https://www.linkedin.com/school/college-of-engineering-guindy/posts/?feedView=all
A8: 7 | B8: AKSHAY KARTHIKEYAN SK | C8: IVP Selected | D8: 9150452331 | E8: SC-2us6k | F8: https://drive.google.com/file/d/1iWc68HJJJgFSsLxllZe3TY45JOCKec0Z/view?usp=sharing | G8: https://www.linkedin.com/in/akshay--sk?utm_source=share&utm_campaign=share_via&utm_content=profile&utm_medium=ios_app | H8: https://www.linkedin.com/school/psg-college-of-technology/
A9: 8 | B9: suraj(8bix) | C9: IVP Selected | D9: 7397252915 | E9: PX-9cgwli | F9: https://docs.google.com/presentation/d/1zZYNJcw9kwJdoQmeNNB9xPR9xS-vA50l/edit?usp=sharing&ouid=104277249549708518105&rtpof=true&sd=true
A10: 9 | B10: selvakumar | C10: IVP Selected | D10: 9176529116 | E10: CEDAU-01 | F10: https://drive.google.com/file/d/1AFBWvei8iUFsbPvbpVzaLqXAFsFu4jvS/view
A11: 10 | B11: saravanan | C11: IVP Selected | D11: 9791005395 | E11: GP-003 | F11: https://docs.google.com/presentation/d/1b5MrpNXt1nMVPylbe9wylHSNXuDk8qDu/edit?usp=sharing&ouid=104277249549708518105&rtpof=true&sd=true | G11: https://www.linkedin.com/in/saravanan-krishnan-26373b5/
A12: 11 | B12: nikarika ramesh | C12: IVP Selected | D12: 9790004554 | E12: SS-xiv9fo | F12: https://docs.google.com/presentation/d/1UuvB8CG5hK21LYH5-VK1-ElnDGm_z_ck/edit?slide=id.p1#slide=id.p1 | G12: https://www.linkedin.com/in/nikarika-ramesh-242842198/
A13: 12 | B13: Jai Ganesh M | C13: IVP Selected | D13: 7358299188 | E13: cedau-03 | F13: https://drive.google.com/file/d/1f0KPgYZmecnbvsrtUrlSgDz0N6apAXyJ/view?usp=drive_link
A14: 13 | B14: Ranjith. K | C14: IVP Selected | D14: 8883035691 | E14: SC-591xv | F14: https://docs.google.com/presentation/d/1if-EUnplBW5VbKgR7L12TzrIzz_2XseW/edit?usp=sharing&ouid=104277249549708518105&rtpof=true&sd=true
A15: 14 | B15: Prathib Vamsi P (2024-25) | C15: IVP Selected | D15: 9003815145 | E15: cedau-06 | F15: https://docs.google.com/presentation/d/1R3kivspd_3Lf6F3BjWMmF6CfZnH8UGnm/edit?usp=drive_link&ouid=104277249549708518105&rtpof=true&sd=true | G15: https://www.linkedin.com/in/prathip-vamsi/
A16: 15 | B16: Satyendra | C16: IVP Selected | D16: 8092225251 | E16: IPO-ozm1k | F16: https://drive.google.com/file/d/18TKSjzu0XBMIfcvR-TzwQO4eOlv5TP4I/view?usp=sharing
A17: 16 | B17: Thanvi | C17: IVP Selected | D17: 9380184164 | E17: SC-ewhypl | F17: https://drive.google.com/file/d/1qUQVHPhnQ3qdrzuMrbhNc2rdmt8eokYp/view?usp=sharing
A18: 17 | B18: Jeremiah Japhet | C18: IVP Selected | D18: 8148091100 | E18: cedau-11 | F18: https://docs.google.com/presentation/d/1EV9T72VDcsImuuEu7YDiejbpGu0Mvy9q/edit?usp=sharing&ouid=104277249549708518105&rtpof=true&sd=true
A19: 18

Sheet  ivp
A1: Name | B1: EMAIL | C1: PASSWORD | E1: grant status | F1: COMPLETED | G1: schedule date | H1: phone no. | I1: team size | J1: Start up incubated | K1: Start up Registered | L1: women beneficiaries | M1: tier | N1: address | O1: gender | P1: caste | Q1: preinc ; whatsapp group | R1: prototyping ; whatsapp group | S1: TEAM ID | T1: pitch deck file | U1: Total amount
A2: sanjeev / ashwin jk | B2: misdautomation@gmail.com | D2: 25-26 | E2: IVP Selected | F2: COMPLETED | G2: 30.06.26 ( Old ) | H2: 9080861148 | I2: 2 founder | Q2: pre | S2: SC-n4aonf | T2: https://docs.google.com/presentation/d/11pbQZHDGUguVuSuwEOLjm3MfecqFhYTM/edit?usp=sharing&ouid=104277249549708518105&rtpof=true&sd=true
A3: Shakthi Prashanth G | D3: 25-26 | E3: not selected | F3: COMPLETED | G3: 14.11.25 | H3: 7358629515 | R3: yes | S3: cedau-02 | T3: https://drive.google.com/file/d/1nMe76mTFPVo5XOKaU2FZJ_icdnBYZdPt/view?usp=sharing
A4: Kota Nageshwar | B4: abikns@gmail.com | C4: Abikns@12 | D4: 25-26 | E4: IVP Selected | F4: COMPLETED | G4: 30.01.26 | H4: 9363300142 | I4: 1 Founder | K4: private | L4: 0 | M4: Tier 1 | N4: 6/31, G-2 raghas flats postal colony 2nd street, west mambalam, chennai -33 | O4: Male | P4: GENERAL | Q4: preinc | R4: yes | S4: CEDAU-07 | T4: https://drive.google.com/file/d/1n3xy0kOxO2Yp2Z-7V4fJMq_x4C118BzN/view?usp=sharing
A5: Reshma Ch | B5: binureshma110@gmail.com | C5: Binureshma@110 | D5: 25-26 | E5: not selected | F5: COMPLETED | G5: 12.01.26 | H5: 9940432697 | M5: Tier 1 | N5: 26 B Sivakami Nagar Korattur Chennai 600076 | O5: Female | P5: GENERAL | R5: yes | S5: CEDAU-04 | T5: https://docs.google.com/presentation/d/1Ntxw63M7DcsoxOIi704XmNM8A5r7ezz0/edit?usp=sharing&ouid=104277249549708518105&rtpof=true&sd=true
A6: Gokkul M | B6: mrgokkul@gmail.com | C6: Gokkul21341. | D6: 25-26 | E6: not selected | F6: COMPLETED | G6: 13.02.26 | H6: 9043405357 | M6: Tier 2 | N6: 2/93-2 Melachithram street, kattuparamakudi taluk, paramakudi, ramanathapuram 623707 | O6: Male | P6: OBC | R6: yes | S6: cedau-05 | T6: https://drive.google.com/file/d/1p4i1zajYvfSaNqnNbQ1cEiLOuEYvjDSJ/view?usp=sharing
A7: Praveen Kumar R | D7: 25-26 | E7: IVP Selected | F7: COMPLETED | G7: 30.01.26 | H7: 8148402208 | I7: 2 Founders + 10 employees | K7: Private | L7: 9 + 2515 other women benenficiaries | M7: Tier 3 | Q7: preinc | R7: yes | S7: cedau-19 | T7: https://docs.google.com/presentation/d/14q8HVWXmbsPywVvXUfo8vnvagpaozDFv/edit?usp=sharing&ouid=104277249549708518105&rtpof=true&sd=true
A8: Semmozhi Selvam S P | B8: semmozhiselvamsp@gmail.com | C8: selv@m2301 | D8: 25-26 | E8: IVP Selected | F8: COMPLETED | G8: 30.01.26 | H8: 6382396276 | I8: 1 Founder | K8: - | L8: 0 | M8: Tier 3 | N8: 121, Agraharam street, vembanoor, Moolangudi post, manjakkudi, KUDAVASAL, THIRUVARUR , 612610 | O8: Male | P8: OBC | Q8: preinc | R8: yes | S8: SC-8heikl | T8: https://docs.google.com/presentation/d/1L7eTzNmLVNQ7B7omSBjUOMv_Fo6yEUuj/edit?usp=sharing&ouid=104277249549708518105&rtpof=true&sd=true
A9: Vishnu Prasanna D | B9: vishnuprasanna.dl@gmail.com | C9: Vishnuprasanna@123 | D9: 25-26 | E9: not selected | F9: COMPLETED | G9: 30.01.26 | H9: 8608487249 | M9: Tier 3 | N9: 413, South Street, Bangalore main road, Thokkavadi, Thukkapet post, Chengam | O9: Male | P9: SC | R9: yes | S9: CEDAU-08 | T9: https://docs.google.com/presentation/d/16s3ed2pzozhPf-uAvWKXGMnci6USeI9O/edit?usp=sharing&ouid=104277249549708518105&rtpof=true&sd=true
A10: Sakthivel S | B10: iyyansoft@gmail.com | C10: Pw4IyyanSoft | D10: 25-26 | E10: not selected | F10: COMPLETED | G10: 21.07.26 | H10: 9944085762 | M10: Tier 1 | N10: Plot 30/2, 2nd St, Ramapuram, Officers Colony, Adambakkam, Chennai, Tamil Nadu 600088 | O10: Male | P10: SC | R10: yes | S10: CEDAU-09 | T10: https://docs.google.com/presentation/d/1PSNb4KAfoToZb3vJ3ZDzvwtjMzaZ7y4H/edit?usp=sharing&ouid=104277249549708518105&rtpof=true&sd=true
A11: Thiru Kumaran Nr | B11: kumaranthiru346@gmail.com | C11: Kumaranthiru@346 | D11: 25-26 | E11: not selected | F11: COMPLETED | G11: 10.03.26 | H11: 7305184227 | M11: Tier 1 | N11: 60, Queen Victoria Road, Ambal City, Poonamallee, 600056 | O11: Male | P11: OBC | R11: yes | S11: CEDAU-10 | T11: https://docs.google.com/presentation/d/1GpS3lq2AUHyhjevALarZz2JiP0aXoCf6/edit?usp=sharing&ouid=104277249549708518105&rtpof=true&sd=true
A12: Ms. M.Nirmaladevi Senthilkumar | B12: amuchitraditionalfoods@gmail.com | C12: Snsurya@1 | D12: 25-26 | E12: IVP Selected | F12: COMPLETED | G12: 29.07.26 | H12: 9688299333 | M12: Tier 2 | N12: No - 23, Sri Ram Nagar, Kooram Gate, Kancheepuram - 631552 | O12: Female | P12: GENERAL | Q12: pre | R12: yes | S12: CEDAU-29 | T12: https://drive.google.com/file/d/1sFC4pPdrt2TlqHFgBbsQ0UUPSKQ--6He/view?usp=sharing
A13: Dr N. Vasudevan | D13: 25-26 | E13: not selected | F13: COMPLETED | G13: 02.03.26 | H13: 9444910521 | R13: yes | S13: CEDAU-12 | T13: https://drive.google.com/file/d/1Em_cP1ecMnwQxTbmcsLeqcczsvVaZdln/view?usp=sharing
A14: Sriranjan | B14: arkfx@tuta.io | C14: Arkfx@12 | D14: 25-26 | E14: IVP Selected | F14: COMPLETED | G14: 29.07.26 | H14: 7358011726 | M14: Tier 1 | N14: 2nd main road , kalaimagal nagar , ekkattuthangal , chennai - | O14: Male | P14: OBC | Q14: preinc | R14: yes | S14: Sc-wx4f45 | T14: https://docs.google.com/presentation/d/1WTC753AOBmjf_nBHKMzSdm2saxshkMHi/edit?usp=sharing&ouid=104277249549708518105&rtpof=true&sd=true
A15: Subanesh | D15: 25-26 | E15: not selected | F15: COMPLETED | G15: 25.05.26 | H15: 7395903061 | S15: cedau-14
A16: P.N. Chendilnadan | F16: not done | S16: cedau-15
A17: Harish Kumar | F17: not done | H17: 8248375363 | S17: cedau-16
A18: Harihara Prabhu | D18: 25-26 | E18: not selected | F18: COMPLETED | H18: 6369492510 | R18: yes | S18: cedau-17 | T18: https://docs.google.com/presentation/d/1prMqTR-f9CdW-27PIrxhheLFhTq5VHGk/edit?usp=sharing&ouid=104277249549708518105&rtpof=true&sd=true
A19: Selvakumar | B19: - | D19: 25-26 | E19: IVP Selected | F19: COMPLETED | G19: 29.07.25 | H19: 9176529116 | I19: 2 Founder | K19: private | M19: Tier 1 | N19: Perungudi, Kancheepuram | O19: Male | P19: OBC | Q19: preinc | R19: yes | S19: CEDAU-01 | T19: https://drive.google.com/file/d/1AFBWvei8iUFsbPvbpVzaLqXAFsFu4jvS/view?usp=drive_link | U19: 3,00,000
A20: Suraj(8Bix) | B20: - | D20: 25-26 | E20: IVP Selected | F20: COMPLETED | G20: 29.07.25 | H20: 7397252915 | I20: 3 Founder | K20: private | L20: 0 | M20: Tier 1 | N20: N.No. 137, O. No.62, V.M. Street, Royapettah, Chennai, Chennai, Tamil Nadu, India, 600014. | Q20: preinc | R20: yes | S20: PX-9cgwli | T20: https://docs.google.com/presentation/d/1zZYNJcw9kwJdoQmeNNB9xPR9xS-vA50l/edit?usp=sharing&ouid=104277249549708518105&rtpof=true&sd=true | U20: 297000
A21: Aarjun Thiagarajan | F21: not done | H21: 8619792227 | S21: CEDAU-20 | T21: nil
A22: Dr.R.Senthilnathan | B22: drsenthil2460@gmail.com | C22: Drsenthil@2460 | D22: 25-26 | E22: absent | F22: COMPLETED | G22: 21.07.26 | H22: 9894119040 | M22: Tier 2 | N22: D10/77 -1b S.G.pudur Arasur Post, coimbatore-641407. Tamil Nadu. | O22: Male | P22: GENERAL | S22: cedau-22 | T22: https://docs.google.com/presentation/d/19KDfehkfiMjlVS4MmIh7c7SpujP0fHpK/edit?usp=sharing&ouid=104277249549708518105&rtpof=true&sd=true
A23: Aathavan Valanarasu | B23: aathavan.valanarasu5@gmail.com | C23: Aathavan@123 | D23: 25-26 | E23: IVP Selected | F23: COMPLETED | G23: 29.07.25 | H23: 9342049639 | I23: 4 Founders | L23: 2 | M23: Tier 1 | N23: Block C2, Toddhunter Nagar, PWD quarters,Saidapet, chennai-15 | O23: Male | P23: OBC | Q23: preinc | R23: yes | S23: SC-rea6ge | T23: https://drive.google.com/file/d/1icj55HRkpEE6D2YhMiuNvMZMm4qS83lU/view?usp=sharing | U23: 300000
A24: Nelson | B24: sathyanelson.m@gmail.com | C24: TrinityWorldReal!7 | D24: 25-26 | E24: not selected | F24: COMPLETED | G24: 05.06.26 | H24: 7358734289 | M24: Tier 1 | N24: SKCL Techsquare, Lazer Stret, South Phase, SIDCO Industrial Estate, Guindy, Chennai | O24: Male | P24: General | R24: yes | S24: cedau-25 | T24: https://docs.google.com/presentation/d/1svlsWidPE9Mo4IunAUtMRWoX6-3FELRG/edit?usp=sharing&ouid=104277249549708518105&rtpof=true&sd=true
A25: Prathib Vamsi P | D25: 25-26 | E25: IVP Selected | F25: COMPLETED | G25: 28.11.25 | H25: 9003815145 | I25: 2 founder +20 emp = 22 | K25: private | L25: 13 | M25: Tier 3 | Q25: preinc | S25: cedau-06 | T25: https://docs.google.com/presentation/d/1R3kivspd_3Lf6F3BjWMmF6CfZnH8UGnm/edit?usp=drive_link&ouid=104277249549708518105&rtpof=true&sd=true | U25: 200000
A26: Navinkrishna K | B26: krishnanavin03@gmail.com | C26: Navi@1 | D26: 25-26 | E26: absent | F26: COMPLETED | G26: 21.07.26 | H26: 8122980305 | M26: Tier 1 | N26: NO.106/1024, T.H ROAD, KALADIPET,THIRUVOTTIYUR | O26: Male | P26: GENERAL | R26: yes | S26: cedau-27 | T26: https://docs.google.com/presentation/d/1d8-jiX9yr-sMsCczAoqAxNddaCFgD9Lb/edit?usp=sharing&ouid=104277249549708518105&rtpof=true&sd=true
A27: G Rathi | B27: rathiraghuprakash@gmail.com | D27: 25-26 | E27: Yet to present | F27: COMPLETED | H27: 9952437272 | R27: yes | S27: CEDAU-28 | T27: https://docs.google.com/presentation/d/1FXIGWLrifrRMQscDpQMdcN-VyYJj8lRY/edit?usp=sharing&ouid=104277249549708518105&rtpof=true&sd=true
A28: Athithya Rayan R | D28: 25-26 | E28: IVP Selected | F28: COMPLETED | G28: 28.11.25 | H28: 6384712172 | I28: 2 founders | J28: kabif - preinc | K28: Private | L28: 0 | M28: Tier 3 | Q28: preinc | R28: yes | S28: cedau-24 | T28: https://drive.google.com/file/d/1TQHqyQdolrHhxhMYy4F0qSG_uUNK2Vpv/view?usp=sharing | U28: 300000
A29: S Varshaa | B29: varshaaselva@gmail.com | C29: Varshaaselva@06 | D29: 25-26 | E29: IVP Selected | F29: COMPLETED | G29: 28.11.25 | H29: 9952048318 | I29: 3 founders | K29: connect to yash | L29: 1 | M29: Tier 1 | N29: No.1,Babuji Nagar, Thiru VI Ka Nagar, Vinayakapuram, Lakshmipuram, Chennai, Tamil Nadu 600066 | O29: Female | P29: OBC | Q29: preinc | R29: yes | S29: SC-ywojqq | T29: https://docs.google.com/presentation/d/1r_uJDDSgeSqdewnxUdc17ddlmhNFHjj7/edit?usp=sharing&ouid=104277249549708518105&rtpof=true&sd=true | U29: 300000
A30: V Vijaya kumar | B30: roxercub@gmail.com | C30: Roxercub@123 | D30: 25-26 | E30: IVP Selected | F30: COMPLETED | G30: 21.07.26 | H30: 9884706822 | Q30: pre | R30: yes | S30: cedau-26 | T30: https://docs.google.com/presentation/d/1F6UprY1Bo46MyZFlV5jxGpMy8RoiGBv4/edit?usp=sharing&ouid=104277249549708518105&rtpof=true&sd=true
A31: Nagendra Dasari | B31: muralidora504@gmail.com | C31: Nagendra@2608 | D31: 25-26 | E31: NOt selected | F31: COMPLETED | G31: 12.08.26 | H31: 8555874504 | M31: Tier 1 | N31: Address of the Company1/37, MIG-II, Block1, TNHB-1500 Flat, SHOLLINGANALLUR, CHENNAI, TAMIL NADU | O31: Male | P31: GENERAL | R31: yes | S31: CEDAU-32 | T31: https://docs.google.com/presentation/d/1gXlydx6GGyjViK9BH2DExwsitvhYxcTC/edit?usp=sharing&ouid=104277249549708518105&rtpof=true&sd=true
A32: kalyani patra | B32: aswiga91@gmail.com | C32: Kalyani*1 | D32: 25-26 | E32: IVP Selected | F32: COMPLETED | G32: 21.07.26 | H32: 8608499779 | M32: Tier 1 | N32: No 1 chithra enclave, Aarthi nagar, East Tambaram | O32: Female | P32: OBC | S32: ipo-28zbru | T32: https://docs.google.com/presentation/d/1YFjs7wBOE-FwqPCIpm92exmo75IKjAZU/edit?usp=sharing&ouid=104277249549708518105&rtpof=true&sd=true
A33: Akash | B33: akashr.annauniv@gmail.com | C33: Akashr.annauniv@12 | D33: 25-26 | E33: NOt selected | F33: COMPLETED | G33: 12.08.26 | H33: 8754728402 | M33: Tier 1 | N33: 69/122, Vannier Street, Chooliamedu, Chennai - 600 094 | O33: Male | P33: SC | R33: yes | S33: CEDAU-34 | T33: https://docs.google.com/presentation/d/1vvNjk_1_mJJVLriLTt7MFXxwPhGuccHt/edit?usp=sharing&ouid=104277249549708518105&rtpof=true&sd=true
A34: Surendar K | B34: arcadeslevel@gmail.com | C34: SIH@aot6 | D34: 25-26 | E34: NOt selected | F34: COMPLETED | G34: 12.08.26 | H34: 93635 32027 | M34: Tier 3 | N34: 118/78,Nappalaya Street,Villupuram,Villupuram - 605602 | O34: Male | P34: OBC | R34: yes | S34: CEDAU-35 | T34: https://drive.google.com/file/d/1iMYV5dCGbdlUDh24yHlB6oced5JQ3Bc2/view?usp=sharing
A35: Hari Krishnan | B35: Tynkohari@123 | C35: harikrisrr@gmail.com | D35: 25-26 | E35: Yet to present | F35: COMPLETED | H35: 8939797268 | R35: yes | S35: CEDAU-36 | T35: https://drive.google.com/file/d/1Jpe5V4pSn5lJy2WIv8hH5IrXrD21Dcd2/view?usp=sharing
A36: Abinaya | B36: abinaya.auceg@gmail.com | C36: ATbian@2026 | D36: 25-26 | E36: Yet to present | F36: COMPLETED | H36: 9080721623 | M36: Tier 2 | N36: 54/3, bypass road, Melasanthapalayam, Musiri, Trichy -621211 | O36: Female | P36: OBC | R36: yes | S36: CEDAU-37 | T36: https://docs.google.com/presentation/d/1mFOPCn7ZHKzvNicJaWvacJD6nFsAMFeD/edit?usp=sharing&ouid=104277249549708518105&rtpof=true&sd=true
A37: Aparup Roy | B37: aparupdgp713217@gmail.com | C37: Gopalmath#713217 | D37: 25-26 | E37: Yet to present | F37: COMPLETED | H37: 9476478885 | M37: Tier 1 | N37: College of Engineering Guindy, Anna University, 12, Sardar Patel Road, Guindy, Chennai, Tamil Nadu, 600025 | O37: Male | P37: GENERAL | R37: yes | S37: cedau-38 | T37: https://drive.google.com/file/d/1ghr4wKJHaB9cM-p8gmva4wiN-FUH3Mmg/view?usp=sharing
A38: Anantha Kumar | B38: Contacts@ztorys.com | C38: Ztorys@2026! | D38: 25-26 | E38: Yet to present | F38: COMPLETED | H38: 7845471602 | M38: Tier 1 | N38: 8th floor, 85, Anna Salai, Guindy Institutional Area, SIDCO Industrial Estate, Guindy, Chennai, Tamil Nadu 600032 | O38: Male | R38: yes | S38: cedau-39 | T38: https://drive.google.com/file/d/1zwrG0J_pCo6yZG42LAl7d5Jx_zdp-LZ_/view?usp=sharing
A39: Kartheka Bojan | B39: karthekabojan@gmail.com | C39: Innovation2026 | D39: 26-27 | E39: Yet to present | F39: COMPLETED | H39: 8870169974 | R39: yes | S39: cedau-40 | T39: https://drive.google.com/file/d/1uDPKPYE5yjMZJlz_KH9e1FA4BpniXAqV/view?usp=sharing
A40: B Arumugapandian | D40: 26-27 | E40: Yet to present | F40: COMPLETED | H40: 9380523384 | S40: cedau-41 | T40: https://docs.google.com/presentation/d/17jQg9XR0LqRPj3eRC3a4YTSCC34bS2xC/edit?usp=sharing&ouid=104277249549708518105&rtpof=true&sd=true
...

Sheet startify3.0
A1: ` | B1: College name | C1: Status Date | D1: Status | E1: Domain | F1: Grant | G1: ivp sno. | H1: PHNO. | I1: TEAMID | J1: pitch manual | K1: pitch sub form | L1: work | M1: in whatsapp group | N1: remarks
A2: 1 | B2: College of Engineering Guindy | C2: 45775 | D2: Selected for Finals | E2: Deep-Tech | F2: 5 | G2: {=_xlfn.XLOOKUP(I2,' ivp'!S:S,#REF!)} -> #N/A | H2: 8883035691 | I2: SC-591xv | J2: =_xlfn.XLOOKUP(I2, ivp!$K:$K, ivp!$M:$M) -> #REF! | K2: {=_xlfn.XLOOKUP(I2,Sheet2!$C$2:$C$56,Sheet2!$G$2:$G$56)} -> #N/A | M2: yes
A3: 2 | B3: St. Joseph's College of Engineering , OMR, Chennai. | C3: 45775 | D3: Selected for Finals | E3: Deep-Tech | F3: 1 | G3: {=_xlfn.XLOOKUP(I3,' ivp'!S:S,#REF!)} -> #N/A | H3: 7812876724 | I3: SC-1ewg7k | J3: =_xlfn.XLOOKUP(I3, ivp!$K:$K, ivp!$M:$M) -> #REF! | K3: {=_xlfn.XLOOKUP(I3,Sheet2!$C$2:$C$56,Sheet2!$G$2:$G$56)} -> #N/A | L3: called | M3: yes | N3: exams
A4: 3 | B4: St. Joseph's College of Engineering , OMR, Chennai. | C4: 45775 | D4: Selected for Finals | E4: Ed-Tech | F4: 5 | G4: {=_xlfn.XLOOKUP(I4,' ivp'!S:S,#REF!)} -> #N/A | H4: 9342049639 | I4: SC-rea6ge | J4: =_xlfn.XLOOKUP(I4, ivp!$K:$K, ivp!$M:$M) -> #REF! | K4: {=_xlfn.XLOOKUP(I4,Sheet2!$C$2:$C$56,Sheet2!$G$2:$G$56)} -> #N/A | M4: no
A5: 4 | B5: University College of Engineering, Thirukkuvalai | C5: 45775 | D5: Selected for Finals | E5: Space-Tech | F5: 6 | G5: {=_xlfn.XLOOKUP(I5,' ivp'!S:S,#REF!)} -> #N/A | H5: 7094149367 | I5: SC-ss0phb | J5: =_xlfn.XLOOKUP(I5, ivp!$K:$K, ivp!$M:$M) -> #REF! | K5: {=_xlfn.XLOOKUP(I5,Sheet2!$C$2:$C$56,Sheet2!$G$2:$G$56)} -> https://drive.google.com/open?id=1DrL3w6tkh8WgbEy3HjkfwRQ93uZiQ4Wz | M5: yes
A6: 5 | B6: St. Joseph's College of Engineering , OMR, Chennai. | C6: 45775 | D6: Selected for Finals | E6: Deep-Tech | F6: 3 | G6: {=_xlfn.XLOOKUP(I6,' ivp'!S:S,#REF!)} -> #N/A | H6: 7200939492 | I6: SC-8s2knl | J6: =_xlfn.XLOOKUP(I6, ivp!$K:$K, ivp!$M:$M) -> #REF! | K6: {=_xlfn.XLOOKUP(I6,Sheet2!$C$2:$C$56,Sheet2!$G$2:$G$56)} -> https://drive.google.com/open?id=1Rbchip-rj68Va3SjmYraQyLPBDxUK_cI | M6: yes
A7: 6 | B7: Mepco Schlenk Engineering College | C7: 45775 | D7: Selected for Finals | E7: AYUSH | F7: 1 | G7: {=_xlfn.XLOOKUP(I7,' ivp'!S:S,#REF!)} -> #N/A | H7: 9342177824 | I7: SC-g2rv7h | J7: =_xlfn.XLOOKUP(I7, ivp!$K:$K, ivp!$M:$M) -> #REF! | K7: {=_xlfn.XLOOKUP(I7,Sheet2!$C$2:$C$56,Sheet2!$G$2:$G$56)} -> #N/A | L7: called | M7: yes | N7: last checks
A8: 7 | B8: Chettinad College of Engineering & Technology | C8: 45776 | D8: Selected to Pre-finals | E8: SaaS | F8: 1 | G8: {=_xlfn.XLOOKUP(I8,' ivp'!S:S,#REF!)} -> #N/A | H8: 7868945597 | I8: SC-mjkoin | J8: =_xlfn.XLOOKUP(I8, ivp!$K:$K, ivp!$M:$M) -> #REF! | K8: {=_xlfn.XLOOKUP(I8,Sheet2!$C$2:$C$56,Sheet2!$G$2:$G$56)} -> #N/A | M8: yes | O8: Startify Status - 1 Yet to Apply Grant, 2 Processed from CED, 3 Grant Application Submitted to Govt., 4 Grant Steering Committee Interview Scheduled, 5 Granted 6 Investor Pitching Requested
A9: 8 | B9: College of Engineering Guindy, Anna University | C9: 45776 | D9: Selected for Finals | E9: MAaaS | F9: 1 | G9: {=_xlfn.XLOOKUP(I9,' ivp'!S:S,#REF!)} -> #N/A | H9: 9123551408 | I9: SC-ebcgyq | J9: =_xlfn.XLOOKUP(I9, ivp!$K:$K, ivp!$M:$M) -> #REF! | K9: {=_xlfn.XLOOKUP(I9,Sheet2!$C$2:$C$56,Sheet2!$G$2:$G$56)} -> #N/A | L9: called | M9: yes
A10: 9 | B10: Mepco Schlenk Engineering College, Sivakasi | C10: 45776 | D10: Selected for Finals | E10: AYUSH | F10: 1 | G10: {=_xlfn.XLOOKUP(I10,' ivp'!S:S,#REF!)} -> #N/A | H10: ​6379986903 | I10: SC-1l7eqi | J10: =_xlfn.XLOOKUP(I10, ivp!$K:$K, ivp!$M:$M) -> #REF! | K10: {=_xlfn.XLOOKUP(I10,Sheet2!$C$2:$C$56,Sheet2!$G$2:$G$56)} -> #N/A | L10: called | M10: yes | N10: he
A11: 10 | B11: Chettinad College of Engineering and Technology | C11: 45776 | D11: Selected to Pre-finals | E11: Agri-Tech | F11: 1 | G11: {=_xlfn.XLOOKUP(I11,' ivp'!S:S,#REF!)} -> #N/A | H11: 8438784753 | I11: SC-l7i27h | J11: =_xlfn.XLOOKUP(I11, ivp!$K:$K, ivp!$M:$M) -> #REF! | K11: {=_xlfn.XLOOKUP(I11,Sheet2!$C$2:$C$56,Sheet2!$G$2:$G$56)} -> #N/A | L11: send pref g invite link | M11: no
A12: 11 | B12: Velammal institute of Technology | C12: 45776 | D12: Selected to Pre-finals | E12: Deep-Tech | F12: 1 | G12: {=_xlfn.XLOOKUP(I12,' ivp'!S:S,#REF!)} -> #N/A | H12: 9600430853 | I12: SC-fg08d | J12: =_xlfn.XLOOKUP(I12, ivp!$K:$K, ivp!$M:$M) -> #REF! | K12: {=_xlfn.XLOOKUP(I12,Sheet2!$C$2:$C$56,Sheet2!$G$2:$G$56)} -> #N/A | M12: yes
A13: 12 | B13: St. Joseph's College of Engineering , OMR, Chennai. | C13: 45776 | D13: Selected for Finals | E13: DaaS | F13: 3 | G13: {=_xlfn.XLOOKUP(I13,' ivp'!S:S,#REF!)} -> #N/A | H13: 8639764726 | I13: SC-wv04l9 | J13: =_xlfn.XLOOKUP(I13, ivp!$K:$K, ivp!$M:$M) -> #REF! | K13: {=_xlfn.XLOOKUP(I13,Sheet2!$C$2:$C$56,Sheet2!$G$2:$G$56)} -> #N/A | M13: yes
A14: 13 | B14: KGiSL Institute of Technology | C14: 45776 | D14: Selected to Pre-finals | E14: SaaS | F14: 1 | G14: {=_xlfn.XLOOKUP(I14,' ivp'!S:S,#REF!)} -> #N/A | H14: 7339614900 | I14: SC-d3cp | J14: =_xlfn.XLOOKUP(I14, ivp!$K:$K, ivp!$M:$M) -> #REF! | K14: {=_xlfn.XLOOKUP(I14,Sheet2!$C$2:$C$56,Sheet2!$G$2:$G$56)} -> #N/A | M14: yes
A15: 14 | B15: R.M.D. Engineering College | C15: 45841 | D15: Selected for Finals | E15: MAaaS | F15: 6 | G15: {=_xlfn.XLOOKUP(I15,' ivp'!S:S,#REF!)} -> #N/A | H15: 8148522265 | I15: SC-oajf6r | J15: =_xlfn.XLOOKUP(I15, ivp!$K:$K, ivp!$M:$M) -> #REF! | K15: {=_xlfn.XLOOKUP(I15,Sheet2!$C$2:$C$56,Sheet2!$G$2:$G$56)} -> https://drive.google.com/open?id=1VWhrxq4im2ROTVEhW3mI93TDMyUbpKfn | M15: yes
A16: 15 | B16: Erode Sengunthar Engineering College | C16: 45776 | D16: Selected to Pre-finals | E16: MAaaS | F16: 1 | G16: {=_xlfn.XLOOKUP(I16,' ivp'!S:S,#REF!)} -> #N/A | H16: 7695916662 | I16: SC-4moum | J16: =_xlfn.XLOOKUP(I16, ivp!$K:$K, ivp!$M:$M) -> #REF! | K16: {=_xlfn.XLOOKUP(I16,Sheet2!$C$2:$C$56,Sheet2!$G$2:$G$56)} -> #N/A | M16: yes
A17: 16 | B17: Meenakshi Sundararajan Engineering College | C17: 45777 | D17: Selected for Finals | E17: Health-Tech | F17: 5 | G17: {=_xlfn.XLOOKUP(I17,' ivp'!S:S,#REF!)} -> #N/A | H17: 7305567239 | I17: PX-9cgwli | J17: =_xlfn.XLOOKUP(I17, ivp!$K:$K, ivp!$M:$M) -> #REF! | K17: {=_xlfn.XLOOKUP(I17,Sheet2!$C$2:$C$56,Sheet2!$G$2:$G$56)} -> https://drive.google.com/open?id=1zZYNJcw9kwJdoQmeNNB9xPR9xS-vA50l | M17: no
A18: 17 | B18: Saveetha Engineering College | C18: 45777 | D18: Selected for Finals | E18: EV Services | F18: 3 | G18: {=_xlfn.XLOOKUP(I18,' ivp'!S:S,#REF!)} -> #N/A | H18: 6381784015 | I18: PX-cm2mr | J18: =_xlfn.XLOOKUP(I18, ivp!$K:$K, ivp!$M:$M) -> #REF! | K18: {=_xlfn.XLOOKUP(I18,Sheet2!$C$2:$C$56,Sheet2!$G$2:$G$56)} -> #N/A | M18: yes
A19: 18 | B19: Sri Sairam Institute of Technology | C19: 45777 | D19: Selected to Pre-finals | E19: MAaaS | F19: 1 | G19: {=_xlfn.XLOOKUP(I19,' ivp'!S:S,#REF!)} -> #N/A | H19: 9003181180 | I19: SC-2t6aon | J19: =_xlfn.XLOOKUP(I19, ivp!$K:$K, ivp!$M:$M) -> #REF! | K19: {=_xlfn.XLOOKUP(I19,Sheet2!$C$2:$C$56,Sheet2!$G$2:$G$56)} -> #N/A | M19: no
A20: 19 | B20: KCG College of Technology | C20: 45777 | D20: Selected for Finals | E20: Climate-Tech | F20: 1 | G20: {=_xlfn.XLOOKUP(I20,' ivp'!S:S,#REF!)} -> #N/A | H20: 7395964806 | I20: SC-qdryod | J20: =_xlfn.XLOOKUP(I20, ivp!$K:$K, ivp!$M:$M) -> #REF! | K20: {=_xlfn.XLOOKUP(I20,Sheet2!$C$2:$C$56,Sheet2!$G$2:$G$56)} -> #N/A | L20: called | M20: yes
A21: 20 | B21: Saveetha Engineering College | C21: 45777 | D21: Selected for Finals | E21: MAaaS | F21: 1 | G21: {=_xlfn.XLOOKUP(I21,' ivp'!S:S,#REF!)} -> #N/A | H21: 8015375750 | I21: SC-en6n7o | J21: =_xlfn.XLOOKUP(I21, ivp!$K:$K, ivp!$M:$M) -> #REF! | K21: {=_xlfn.XLOOKUP(I21,Sheet2!$C$2:$C$56,Sheet2!$G$2:$G$56)} -> https://drive.google.com/open?id=1NXq1MT1nOZOwoEwzjtHP8wfEw4HrFKUH | L21: need to apply ivp | M21: yes
A22: 21 | B22: R.M.K. Engineering College | C22: 45778 | D22: Selected for Finals | E22: MAaaS | F22: 1 | G22: {=_xlfn.XLOOKUP(I22,' ivp'!S:S,#REF!)} -> #N/A | H22: 9677277149 | I22: SC-paxd4f | J22: =_xlfn.XLOOKUP(I22, ivp!$K:$K, ivp!$M:$M) -> #REF! | K22: {=_xlfn.XLOOKUP(I22,Sheet2!$C$2:$C$56,Sheet2!$G$2:$G$56)} -> #N/A | L22: called | M22: yes
A23: 22 | B23: SRM IST TRICHY | C23: 45778 | D23: Selected for Finals | E23: Enviro-Tech | F23: 3 | G23: {=_xlfn.XLOOKUP(I23,' ivp'!S:S,#REF!)} -> #N/A | H23: 7845414195 | I23: PX-3ki6nj | J23: =_xlfn.XLOOKUP(I23, ivp!$K:$K, ivp!$M:$M) -> #REF! | K23: {=_xlfn.XLOOKUP(I23,Sheet2!$C$2:$C$56,Sheet2!$G$2:$G$56)} -> #N/A | M23: no
A24: 23 | B24: Velalar College of Engineering and Technology | C24: 45778 | D24: Selected for Finals | E24: Agri-Tech | F24: 3 | G24: {=_xlfn.XLOOKUP(I24,' ivp'!S:S,#REF!)} -> #N/A | H24: 9361054415 | I24: SC-07g6mo | J24: =_xlfn.XLOOKUP(I24, ivp!$K:$K, ivp!$M:$M) -> #REF! | K24: {=_xlfn.XLOOKUP(I24,Sheet2!$C$2:$C$56,Sheet2!$G$2:$G$56)} -> https://drive.google.com/open?id=1zH7oPcHBU2ypBkNZMJ-UzIHydcevpHCz | M24: no
A25: 24 | B25: R.M.K. Engineering College | C25: 45779 | D25: Selected to Pre-finals | E25: MAaaS | F25: 1 | G25: {=_xlfn.XLOOKUP(I25,' ivp'!S:S,#REF!)} -> #N/A | H25: 8610937637 | I25: SC-4dv97 | J25: =_xlfn.XLOOKUP(I25, ivp!$K:$K, ivp!$M:$M) -> #REF! | K25: {=_xlfn.XLOOKUP(I25,Sheet2!$C$2:$C$56,Sheet2!$G$2:$G$56)} -> #N/A | M25: yes
A26: 25 | B26: R.M.D. Engineering College | C26: 45779 | D26: Selected to Pre-finals | E26: MAaaS | F26: 1 | G26: {=_xlfn.XLOOKUP(I26,' ivp'!S:S,#REF!)} -> #N/A | H26: 7418496591 | I26: SC-u1zyff | J26: =_xlfn.XLOOKUP(I26, ivp!$K:$K, ivp!$M:$M) -> #REF! | K26: {=_xlfn.XLOOKUP(I26,Sheet2!$C$2:$C$56,Sheet2!$G$2:$G$56)} -> #N/A | L26: send pref g invite link | M26: no
A27: 26 | B27: R.M.K. Engineering College | C27: 45779 | D27: Selected to Pre-finals | E27: MAaaS | F27: 1 | G27: {=_xlfn.XLOOKUP(I27,' ivp'!S:S,#REF!)} -> #N/A | H27: 8838118951 | I27: SC-4lbm5d | J27: =_xlfn.XLOOKUP(I27, ivp!$K:$K, ivp!$M:$M) -> #REF! | K27: {=_xlfn.XLOOKUP(I27,Sheet2!$C$2:$C$56,Sheet2!$G$2:$G$56)} -> #N/A | M27: no
A28: 27 | B28: AAA College of Engineering and Technology | C28: 45779 | D28: Selected for Finals | E28: MAaaS | F28: 1 | G28: {=_xlfn.XLOOKUP(I28,' ivp'!S:S,#REF!)} -> #N/A | H28: 7695851661 | I28: SC-ft2xkq | J28: =_xlfn.XLOOKUP(I28, ivp!$K:$K, ivp!$M:$M) -> #REF! | K28: {=_xlfn.XLOOKUP(I28,Sheet2!$C$2:$C$56,Sheet2!$G$2:$G$56)} -> #N/A | L28: called | M28: yes
A29: 28 | B29: Madras Institute of Technology, Chromepet | C29: 45779 | D29: Selected for Finals | E29: Health-Tech | F29: 1 | G29: {=_xlfn.XLOOKUP(I29,' ivp'!S:S,#REF!)} -> #N/A | H29: 8610254655 | I29: SC-yd0hxd | J29: =_xlfn.XLOOKUP(I29, ivp!$K:$K, ivp!$M:$M) -> #REF! | K29: {=_xlfn.XLOOKUP(I29,Sheet2!$C$2:$C$56,Sheet2!$G$2:$G$56)} -> #N/A | L29: called | M29: no
A30: 29 | B30: Adhiyamaan College of Agriculture and Research | C30: 45779 | D30: Selected for Finals | E30: Agri-Tech | F30: 6 | G30: {=_xlfn.XLOOKUP(I30,' ivp'!S:S,#REF!)} -> #N/A | H30: 6385256271 | I30: SC-oyp2ts | J30: =_xlfn.XLOOKUP(I30, ivp!$K:$K, ivp!$M:$M) -> #REF! | K30: {=_xlfn.XLOOKUP(I30,Sheet2!$C$2:$C$56,Sheet2!$G$2:$G$56)} -> https://drive.google.com/open?id=12RsdTu1tH7jx2uQYyNA2C3v1dFMkZU0H | L30: send f g invite link | M30: no
A31: 30 | B31: R.M.K. Engineering College | C31: 45779 | D31: Selected for Finals | E31: Ed-Tech | F31: 3 | G31: {=_xlfn.XLOOKUP(I31,' ivp'!S:S,#REF!)} -> #N/A | H31: 9952048318 | I31: SC-ywojqq | J31: =_xlfn.XLOOKUP(I31, ivp!$K:$K, ivp!$M:$M) -> #REF! | K31: {=_xlfn.XLOOKUP(I31,Sheet2!$C$2:$C$56,Sheet2!$G$2:$G$56)} -> https://docs.google.com/presentation/d/1r_uJDDSgeSqdewnxUdc17ddlmhNFHjj7/edit?usp=sharing&ouid=104277249549708518105&rtpof=true&sd=true | M31: yes
A32: 31 | B32: R.M.K. Engineering College | C32: 45779 | D32: Selected for Finals | E32: MAaaS | F32: 1 | G32: {=_xlfn.XLOOKUP(I32,' ivp'!S:S,#REF!)} -> #N/A | H32: 9788606171 | I32: SC-1k48n8 | J32: =_xlfn.XLOOKUP(I32, ivp!$K:$K, ivp!$M:$M) -> #REF! | K32: {=_xlfn.XLOOKUP(I32,Sheet2!$C$2:$C$56,Sheet2!$G$2:$G$56)} -> #N/A | L32: called | M32: yes | N32: last checks
A33: 32 | B33: R.M.K. Engineering College | C33: 45779 | D33: Selected for Finals | E33: MAaaS | F33: 1 | G33: {=_xlfn.XLOOKUP(I33,' ivp'!S:S,#REF!)} -> #N/A | H33: 8825400260 | I33: SC-wl7dmv | J33: =_xlfn.XLOOKUP(I33, ivp!$K:$K, ivp!$M:$M) -> #REF! | K33: {=_xlfn.XLOOKUP(I33,Sheet2!$C$2:$C$56,Sheet2!$G$2:$G$56)} -> #N/A | L33: called | M33: yes | N33: get back
A34: 33 | B34: Sathyabama Institute of Science and Technology | C34: 45779 | D34: Selected to Pre-finals | E34: Deep-Tech | F34: 1 | G34: {=_xlfn.XLOOKUP(I34,' ivp'!S:S,#REF!)} -> #N/A | H34: 9025456450 | I34: SC-jxifzd | J34: =_xlfn.XLOOKUP(I34, ivp!$K:$K, ivp!$M:$M) -> #REF! | K34: {=_xlfn.XLOOKUP(I34,Sheet2!$C$2:$C$56,Sheet2!$G$2:$G$56)} -> #N/A | M34: yes
A35: 34 | B35: Panimalar Engineering College | C35: 45960 | D35: Selected for Finals | E35: blank | F35: 3 | G35: {=_xlfn.XLOOKUP(I35,' ivp'!S:S,#REF!)} -> #N/A | H35: 6374990762 | I35: SC-pcw53a | J35: =_xlfn.XLOOKUP(I35, ivp!$K:$K, ivp!$M:$M) -> #REF! | K35: {=_xlfn.XLOOKUP(I35,Sheet2!$C$2:$C$56,Sheet2!$G$2:$G$56)} -> #N/A | L35: called | M35: yes | N35: company incorporation
A36: 35 | B36: Rajalakshmi Engineering College | C36: 45780 | D36: Selected to Pre-finals | E36: blank | F36: 1 | G36: {=_xlfn.XLOOKUP(I36,' ivp'!S:S,#REF!)} -> #N/A | H36: 9360341516 | I36: SC-l8l0si | J36: =_xlfn.XLOOKUP(I36, ivp!$K:$K, ivp!$M:$M) -> #REF! | K36: {=_xlfn.XLOOKUP(I36,Sheet2!$C$2:$C$56,Sheet2!$G$2:$G$56)} -> #N/A | L36: send pref g invite link | M36: no
A37: 36 | B37: R.M.K College of Engineering and Technology, Tiruvallur | C37: 45780 | D37: Selected for Finals | E37: Automobile | F37: 1 | G37: {=_xlfn.XLOOKUP(I37,' ivp'!S:S,#REF!)} -> #N/A | H37: 8940116891 | I37: SC-4yp9l | J37: =_xlfn.XLOOKUP(I37, ivp!$K:$K, ivp!$M:$M) -> #REF! | K37: {=_xlfn.XLOOKUP(I37,Sheet2!$C$2:$C$56,Sheet2!$G$2:$G$56)} -> #N/A | L37: called | M37: no | N37: exams
A38: 37 | B38: Jansons Institute of Technology | C38: 45780 | D38: Selected for Finals | E38: Industrial IoT /Smart City | F38: 1 | G38: {=_xlfn.XLOOKUP(I38,' ivp'!S:S,#REF!)} -> #N/A | H38: 8148232205 | I38: SC-mnnn9n | J38: =_xlfn.XLOOKUP(I38, ivp!$K:$K, ivp!$M:$M) -> #REF! | K38: {=_xlfn.XLOOKUP(I38,Sheet2!$C$2:$C$56,Sheet2!$G$2:$G$56)} -> https://drive.google.com/open?id=1Kkw_iTDBFZV0hwN1-vITM_lwyEMhi6Dw | L38: called | M38: no
A39: 38 | B39: Erode Sengunthar Engineering College | C39: 45782 | D39: Selected to Pre-finals | E39: Deep-Tech | F39: 1 | G39: {=_xlfn.XLOOKUP(I39,' ivp'!S:S,#REF!)} -> #N/A | H39: 9360119932 | I39: SC-y43euj | J39: =_xlfn.XLOOKUP(I39, ivp!$K:$K, ivp!$M:$M) -> #REF! | K39: {=_xlfn.XLOOKUP(I39,Sheet2!$C$2:$C$56,Sheet2!$G$2:$G$56)} -> https://drive.google.com/open?id=1nOtcqzNxnN1cVZZNgYC7O4pMceJ1vuq4 | M39: yes
A40: 39 | B40: R.M.K. Engineering College | C40: 45782 | D40: Selected for Finals | E40: Deep-Tech | F40: 3 | G40: {=_xlfn.XLOOKUP(I40,' ivp'!S:S,#REF!)} -> #N/A | H40: 7708365986 | I40: SC-b4jkfxa | J40: =_xlfn.XLOOKUP(I40, ivp!$K:$K, ivp!$M:$M) -> #REF! | K40: {=_xlfn.XLOOKUP(I40,Sheet2!$C$2:$C$56,Sheet2!$G$2:$G$56)} -> https://drive.google.com/open?id=1VorSWnUlyM-hZbEwKD3-ydU3amct_rNZ | M40: yes
...

Sheet Sheet2
A1: Column 8 | B1: cross verfy start sno. | C1: Team ID | D1: Primary Contact Name | E1: Primary contact no. | F1: Primary Email. | G1: Please upload your Pitch presentation
B2: {=_xlfn.XLOOKUP(C2,Table1_2[TEAMID],Table1_2[`])} -> #N/A | C2: CEDAU-04 | D2: RESHMA C H | E2: 9940432697 | F2: binureshma110@gmail.com | G2: https://drive.google.com/open?id=1Ntxw63M7DcsoxOIi704XmNM8A5r7ezz0
B3: {=_xlfn.XLOOKUP(C3,Table1_2[TEAMID],Table1_2[`])} -> #N/A | C3: CEDAU-08 | D3: VISHNU PRASANNA DEVARAJAN | E3: 8608487249 | F3: vishnuprasanna.dl@gmail.com | G3: https://drive.google.com/open?id=16s3ed2pzozhPf-uAvWKXGMnci6USeI9O
B4: {=_xlfn.XLOOKUP(C4,Table1_2[TEAMID],Table1_2[`])} -> 144 | C4: GP-1bjcbo | D4: Saravanan K | E4: 9791005395 | F4: saravanankrish@annauniv.edu | G4: https://drive.google.com/open?id=1b5MrpNXt1nMVPylbe9wylHSNXuDk8qDu
B5: {=_xlfn.XLOOKUP(C5,Table1_2[TEAMID],Table1_2[`])} -> 145 | C5: GP-zvvwzi | D5: Dr.P.Ganesh Kumar | E5: 9791638370 | F5: drganesh30@gmail.com | G5: https://drive.google.com/open?id=1RaSKcvZtyuFxCyemLEnoqYmV2Y58scdO
B6: {=_xlfn.XLOOKUP(C6,Table1_2[TEAMID],Table1_2[`])} -> 114 | C6: PX-875q6 | D6: vetriprasath V | E6: 9600407657 | F6: vetriprasath59@gmail.com | G6: https://drive.google.com/open?id=1kkTkDVzx7IcjWyCseEaZRkQ-xYIfc6PJ
B7: {=_xlfn.XLOOKUP(C7,Table1_2[TEAMID],Table1_2[`])} -> 16 | C7: PX-9cgwli | D7: Suraj | E7: 7397252915 | F7: 8bix2024@gmail.com | G7: https://drive.google.com/open?id=1zZYNJcw9kwJdoQmeNNB9xPR9xS-vA50l
B8: {=_xlfn.XLOOKUP(C8,Table1_2[TEAMID],Table1_2[`])} -> 136 | C8: PX-xocu6 | D8: Antanet Anusha G | E8: 9384233122 | F8: anuthiraviam@gmail.com | G8: https://drive.google.com/open?id=1GTUuQ193iH8aPr4qTGOjSh7oj8tF1aN7
B9: {=_xlfn.XLOOKUP(C9,Table1_2[TEAMID],Table1_2[`])} -> 23 | C9: SC-07G6MO | D9: Tharaneeshwaran A | E9: 9361054415 | F9: tharaneeshwaran5555@gmail.com | G9: https://drive.google.com/open?id=1zH7oPcHBU2ypBkNZMJ-UzIHydcevpHCz
B10: {=_xlfn.XLOOKUP(C10,Table1_2[TEAMID],Table1_2[`])} -> 104 | C10: SC-1uzde | D10: Thilagaraaj .J | E10: 7845127728 | F10: 24it177@stjosephs.ac.in | G10: https://drive.google.com/open?id=1h9tBZeIaTYj8Em_ZR4Zz4Hh5uaf9SDvU
B11: {=_xlfn.XLOOKUP(C11,Table1_2[TEAMID],Table1_2[`])} -> #N/A | C11: SC-2aiz3p | D11: Mukeshkumar M | E11: 6380568055 | F11: mukeshkumar.cse24@gmail.com | G11: https://drive.google.com/open?id=1UJbWZgyLzAlkh7J9SHcaH0BMVLJ5RJMx
B12: {=_xlfn.XLOOKUP(C12,Table1_2[TEAMID],Table1_2[`])} -> #N/A | C12: SC-321ex | D12: Jayashree M | E12: 9344599054 | F12: jayashreemad0505@gmail.com | G12: https://drive.google.com/open?id=1MfHI_NNqr7AkbgYK9KOLmgUp_0weURL_
B13: {=_xlfn.XLOOKUP(C13,Table1_2[TEAMID],Table1_2[`])} -> 200 | C13: SC-3gcyak | D13: Muni Chandrasekar Reddy K | E13: 9962764646 | F13: kmcr2005@gmail.com | G13: https://drive.google.com/open?id=1uK1jvNK5uZzUPeWETKPYgSroJ5mXheZM
... B56: {=_xlfn.XLOOKUP(C56,Table1_2[TEAMID],Table1_2[`])} -> #N/A | C56: VEN-ZEPH-2773 | D56: Nevan.L | E56: 9445633545 | F56: nevan.28ee@licet.ac.in | G56: https://drive.google.com/open?id=1GgAzrhaWcpBPQsW6zHRD2g3L7XVQbRBh

Sheet review schedule
A1: letter no. : | C1: Name | D1: COMPLETED | E1: Contact | F1: TEAM ID | G1: startup name | H1: Domain | I1: Session no. | J1: College name
A2: blank | C2: Prathib Vamsi P | D2: COMPLETED | E2: 9003815145 | F2: cedau-06 | G2: MotorX Mobility Private Limited | H2: Consumables | I2: S6 | J2: EDII-TN
A3: 26 | C3: Aswath Vishnu.E | D3: COMPLETED | E3: 7845414195 | F3: PX-3ki6nJ | G3: ChrysoLux | H3: Enviro-Tech | I3: S5 | J3: SRM IST TRICHY
A4: 27 | B4: 1 | C4: Anjanarangarajan | D4: COMPLETED | E4: 9790339415 | F4: SC-9au7v | G4: Nova AI | H4: ai | I4: S1 | J4: St. Joseph's College of Engineering , OMR, Chennai.
A5: 31 | B5: 2 | C5: Armaan Patnaik | D5: COMPLETED | E5: 8939077434 | F5: SC-eanbmk | G5: FIOXYY-NEURAGENT | H5: ai | I5: S1 | J5: Madras Institute of Technology, Chromepet
A6: 25 | B6: 3 | C6: Arun Nivethan | D6: COMPLETED | E6: 7539960504 | F6: SC-ireg2m | G6: SPACE CRAFT AI | H6: ai | I6: S1 | J6: Sri Sairam Institute of Technology
A7: 30 | B7: 4 | C7: Aadhavan Valanarasu | D7: COMPLETED | E7: 9342049639 | F7: SC-rea6ge | G7: Niya Therapy Hub | H7: Ed-Tech | I7: S8 | J7: St. Joseph's College of Engineering , OMR, Chennai.
A8: 28 | C8: Sadhana | D8: COMPLETED | E8: 6385256271 | F8: SC-oyp2ts | G8: GeneGlow | H8: Agri-Tech | I8: S4 | J8: Adhiyamaan College of Agriculture and Research
A9: 33 | B9: 5 | C9: Shirish | D9: COMPLETED | E9: 8939747045 | F9: SC-hetzhm | G9: PickMyseat.ai | H9: ai | I9: S1 | J9: College of Engineering, Guindy
A10: 41 | B10: 6 | C10: Faheera Umu Salma | D10: COMPLETED | E10: 8681879364 | F10: SC(BT)-fFRV5 | G10: Diagnobee | H10: Med-Tech | I10: S7 | J10: Alagappa College of Technology
A11: 43 | C11: Deepika | D11: COMPLETED | E11: 7395956159 | F11: SC-qtithv | G11: Diatech | H11: Health-Tech | I11: S7 | J11: Sri Sairam Homoeopathy Medical College and Research Centre
A12: 42 | B12: 7 | C12: Saravanan | D12: COMPLETED | E12: 9791005395 | F12: GP-003 | G12: Animal Tradex | H12: ai | I12: S1 | J12: Faculty, CEG
A13: 45 | C13: Tharaneeswharan | D13: COMPLETED | E13: 9361054415 | F13: SC-07g6mo | G13: UZHAVAN | H13: Enviro-Tech | I13: S4 | J13: Velalar College of Engineering and Technology
A14: 44 | B14: 8 | C14: Shanmuga Pradeepan R | D14: COMPLETED | E14: 8438532004 | F14: SC-dg0km | G14: Edufyte | H14: ai | I14: S1 | J14: Sethu Institute of Technology
A15: blank | B15: 9 | C15: Vijay Krishnan | D15: COMPLETED | E15: 7305499740 | F15: SC-9e48xs | G15: Vision Solve | H15: Ed-Tech | I15: S8 | J15: College of Engineering, Guindy
A16: blank | B16: 10 | C16: Priya Roshni A | D16: COMPLETED | E16: 9363197584 | F16: SC-vnqnnm | G16: Orion AI | H16: ai | I16: S1 | J16: Vels University
A17: 52 | C17: Vetriprasath | D17: COMPLETED | E17: 9600407657 | F17: PX-875q6 | G17: DizziGuard | H17: Health-Tech | I17: S7 | J17: SRM IST TRICHY
A18: 48 | C18: Shakthi Prashanth G | D18: COMPLETED | E18: 7358629515 | F18: cedau-02 | G18: Gig AI Labs | H18: ai | I18: S1 | J18: EDII-TN
A19: 50 | C19: Ruthresh A | D19: COMPLETED | E19: 9003530044 | F19: CEDAU-33 | G19: Vitron | H19: ai | I19: S1 | J19: startup Walk in
A20: 49 | C20: Antanet Anusha G | D20: COMPLETED | E20: 9384233122 | F20: Px-xocu6 | G20: Millet-Based Electrolyte Beverages | H20: Food tech | I20: S4 | J20: Alagappa College of Technology
A21: 51 | C21: Sandiep Lakshman | D21: COMPLETED | E21: 9944039984 | F21: SC-vm5wp7 | G21: EternalEnergy | H21: Renewable Energy | I21: S5 | J21: College of Engineering, Guindy
A22: 52 | B22: 11 | C22: S Varshaa | D22: COMPLETED | E22: 9952048318 | F22: SC-ywojqq | G22: Learnsphere | H22: Ed-Tech | I22: S8 | J22: R.M.K. Engineering College
A23: 39 | C23: Purushothaman J | D23: COMPLETED | E23: 9176435615 | F23: SC-aodnso | G23: Grainforge3D Printer | H23: Industry 4.0 | I23: S3 | J23: College of Engineering, Guindy
A24: 55 | C24: Santhoshkumar P | D24: COMPLETED | E24: 9843930292 | F24: SC-Votrgd | G24: FITNGRO | H24: Health-Tech | I24: S7 | J24: P.A. College of Engineering and Technology
A25: 56 | C25: Mohammed Hussain Basith | D25: COMPLETED | E25: 7200326094 | F25: SC-83s9eo | G25: OCEAN WAVE ENERGY CONVERTER | H25: Renewable Energy | I25: S5 | J25: Madras Institute of Technology, Chromepet
C26: Mukesh Kumar R | D26: COMPLETED | E26: 8122687750 | F26: SC-fmdki | G26: RMK Aerospace and Sustainable Technology Private Limited | H26: Enviro-Tech | I26: S5 | J26: KCG College of Technology
A27: blank | C27: Vishnu Priya V | D27: COMPLETED | E27: 9789962388 | F27: SS-e7fr19 | G27: indyarn Clean Tech | H27: Agri-Tech | I27: S4 | J27: Alagappa College of Technology
A28: 61 | C28: Akshey Karthikeyan SK | D28: COMPLETED | E28: 9150452331 | F28: SC-2us6k | G28: Curio | H28: Fashion | I28: S6 | J28: PSG College of Technology, Coimbatore
A29: 60 | C29: Kotha Vamsi | D29: COMPLETED | E29: 6381784015 | F29: PX-cm2mr | G29: CHARGE ONE | H29: Auto ; EV | I29: S5 | J29: Saveetha Engineering College
A30: blank | B30: 12 | C30: Harini Premkumar | D30: COMPLETED | E30: 6381337230 | F30: SC-j51bjj | G30: Spar Shield+ | H30: Med-Tech | I30: S7 | J30: R.M.K. Engineering College
A31: blank | C31: Anantha Kumar | D31: COMPLETED | E31: 7845471602 | F31: cedau-39 | G31: Ztorys | H31: ai | I31: S1 | J31: startup Walk in
B32: 13 | C32: S Jeevesh | D32: COMPLETED | E32: 9025314278 | F32: SC-dyjltj | G32: Navogenix Technologies | H32: ai | I32: S1 | J32: Panimalar Engineering College
A33: blank | C33: Reshma Ch | D33: COMPLETED | E33: 9940432697 | F33: CEDAU-04 | G33: SanBio 360 | H33: Bio-Tech | I33: S7 | J33: College of Engineering, Guindy
A34: blank | B34: 14 | C34: Shabeera S | D34: COMPLETED | E34: 9042934637 | F34: SC-i8ijt | G34: SPEAK KARO | H34: Ed-Tech | I34: S8 | J34: Anand Institute of Higher Technology
A35: 57 | B35: 15 | C35: Ganesh Kumar P | D35: COMPLETED | E35: 9791638370 | F35: GP-zvvwzi | G35: UPI.Direct | H35: FinTech | I35: S8 | J35: College of Engineering, Guindy
A36: blank | B36: 16 | C36: Thanvi M | D36: COMPLETED | E36: 9380184164 | F36: SC-ewhypl | G36: SafeStride Tech | H36: ai | I36: S1 | J36: R.M.K. Engineering College
A37: blank | C37: Semmozhi Selvam S P | D37: COMPLETED | E37: 6382396276 | F37: SC-8heikl | G37: Quick Glow | H37: Consumables | I37: S6 | J37: College of Engineering, Guindy
A38: blank | C38: Kota Nageshwar | D38: COMPLETED | E38: 9363300142 | F38: CEDAU-07 | G38: Swatch Water Filters | H38: Consumables | I38: S6 | J38: Startup Walk in
A39: 29 | B39: 17 | C39: Satyendra / Lakshmi Priya | D39: COMPLETED | E39: 8092225251 | F39: IPO-ozm1k | G39: Scout Edge | H39: ai | I39: S1 | J39: IIT Madras
A40: 35 | B40: 18 | C40: Keerthana | D40: COMPLETED | E40: 8122302503 | F40: SC(BT)-36X8Y | G40: EcoShieldSPF | H40: Med-Tech | I40: S7 | J40: Alagappa College of Technology
...

Sheet all funds -1926
A1: S.NO | B1: NAME | C1: COMPANY / PRODUCT NAME | D1: THRUST AREA | E1: Funding Scheme | F1: AMOUNT
A2: 1 | B2: Aadhavan Valanarasu | C2: Niya Therapy Hub | D2: AR/VR | E2: IVP | F2: ₹ 3,00,000
A3: 2 | B3: AKASH RS | C3: Veducate Skills and Technologies | D3: EduTech | E3: IVP | F3: ₹ 3,00,000
A4: 3 | B4: Akshey Karthikeyan SK | C4: Curio | D4: Fashion Tech | E4: IVP | F4: ₹ 3,00,000
A5: 4 | B5: Alex | C5: Geosonic | D5: Automobile | E5: IVP | F5: ₹ 3,00,000
A6: 5 | B6: Alex Bruno | C6: George Multitech System | D6: Industry 4.0 | E6: IVP | F6: ₹ 7,00,000
A7: 6 | B7: Aruldha Raja Aiswarya CA | C7: Nova Bottles | D7: Marine Tech | E7: Balakamalam | F7: ₹ 50,000
A8: 7 | B8: Aruldha Raja Aiswarya CA | C8: NOVA Ecotech | D8: Marine Tech | E8: IVP | F8: ₹ 2,93,000
A9: 8 | B9: Athithya Rayan | C9: Hybrid Biofertilizer (Magasool) | D9: Agri | E9: IVP | F9: ₹ 3,00,000
A10: 9 | B10: Ayush Upadhyay | C10: Crisp Roots | D10: Agri Tech | E10: Balakamalam | F10: ₹ 50,000
A11: 10 | B11: Chandrika Murali | C11: Fusillade Innotech Ventures | D11: IOT | E11: SISFS | F11: ₹ 10,00,000
A12: 11 | B12: Deepika | C12: Diatech | D12: MedTech | E12: IVP | F12: ₹ 3,00,000
A13: 12 | B13: Ezhilarasan M | C13: CARBONERGY CONSULTANCY | D13: IOT | E13: IVP | F13: ₹ 2,00,000
... A17: 16 | B17: Jai Ganesh M | C17: Intra Mobility and Precision System Pvt Ltd | D17: Electronic Consumables | E17: IVP | F17: ₹ 3,00,000
A18: 17 | B18: Janani Selvaganesh | C18: Verdent Vision | E18: IVP | F18: ₹ 2,60,000
A19: 18 | B19: Jeremiah Japheth | C19: CEG Motors | D19: Automobile | E19: IVP | F19: ₹ 2,97,000
A20: 19 | B20: Jeremiah Japheth | C20: CEG Motors | D20: Automobile | E20: EDII-TN | F20: ₹ 2,34,000
A21: 20 | B21: kalyani patra | C21: Vetri | D21: Deep Tech | E21: IVP | F21: ₹ 3,00,000
A22: 21 | B22: Karunakaran | C22: Pro Eduvate | E22: IVP | F22: ₹ 3,00,000
A23: 22 | B23: Kaviya Kannan | C23: Cold Storage | D23: Agri Tech | E23: Balakamalam | F23: ₹ 30,000
A24: 23 | B24: Kochadai M | C24: Ziggers | D24: SAAS | E24: IVP | F24: ₹ 3,00,000
A25: 24 | B25: Kota Nageshwar | C25: Swatch Water Filters | D25: IOT | E25: IVP | F25: ₹ 3,00,000
A26: 25 | B26: Lakshmi Priya | C26: Scout Edge | D26: Sports Tech | E26: IVP | F26: ₹ 3,00,000
A27: 26 | B27: Liya Therese A J | C27: PlantIn | D27: Agri | E27: Balakamalam | F27: ₹ 50,000
A28: 27 | B28: maharaja pandian G | C28: Biomediac Solution X | D28: BioTech | E28: IVP | F28: ₹ 3,00,000
A29: 28 | B29: Mohammed Roshan Ibrahim | C29: Hyrowah | D29: Water Tech | E29: Balakamalam | F29: ₹ 50,000
A30: 29 | B30: Mohammed Roshan Ibrahim | C30: Hyrowah | D30: Renewables | E30: IVP | F30: ₹ 3,00,000
A31: 30 | B31: Ms. M.Nirmaladevi Senthilkumar | C31: Namma ammuchi tradition foods | D31: Food Tech | E31: IVP | F31: ₹ 3,00,000
A32: 31 | B32: Mukesh Kumar R | C32: RMK | D32: Waste to Wealth | E32: GTP | F32: ₹ 1,00,000
A33: 32 | B33: Muruganantham R | C33: Global Technologies | E33: IVP | F33: ₹ 3,00,000
A34: 33 | B34: Muni Chandrasekar Reddy | C34: Apex | D34: SAAS | E34: IVP | F34: ₹ 2,97,000
A35: 34 | B35: Nikarika Ramesh | C35: Vitasafe | D35: MedTech | E35: IVP | F35: ₹ 3,00,000
A36: 35 | B36: P. Paneer Selvam / Krishna kumar | C36: Leogar Renewables | D36: Renewables | E36: IVP | F36: ₹ 3,00,000
A37: 36 | B37: Prathib Vamsi P | C37: MotorX Mobility Private Limited | D37: Automobile | E37: IVP | F37: ₹ 9,00,000
A38: 37 | B38: Prathib Vamsi P | C38: MotorX Mobility Private Limited | D38: Automobile | E38: TANSEED | F38: ₹ 10,00,000
A39: 38 | B39: Praveen B B | C39: PraIOT | D39: IOT | E39: GTP | F39: ₹ 1,00,000
A40: 39 | B40: Praveen B B | C40: PraIOT | D40: IOT | E40: IVP | F40: ₹ 2,88,000
A41: 40 | B41: Praveen Kumar R | C41: Namma Vivasayi | D41: Agri Tech | E41: IVP | F41: ₹ 3,00,000
A42: 41 | B42: Prempradeep S | C42: Aquaholics | D42: Industry 4.0 | E42: IVP | F42: ₹ 3,00,000
A43: 42 | B43: Prempradeep S | C43: Aquaholics | D43: Industry 4.0 | E43: Internal Hackhathon | F43: ₹ 1,000
...

Sheet ivp - problem statement
A1: Si.no | B1: NAME | C1: IVP - STATUS | D1: submission date | E1: phone no. | F1: cross verify sno. | G1: preinc ; whatsapp group | H1: prototyping ; whatsapp group | I1: TEAM ID | J1: Domain Tags | K1: pitch deck file | L1: problem statement
A2: 1 | B2: Ruthresh A | C2: COMPLETED | E2: 9003530044 | F2: {=_xlfn.XLOOKUP(I2,startify3.0!I:I,startify3.0!A:A)} -> #N/A | H2: yes | I2: CEDAU-33 | J2: AI / ML, Fashion , App Development / Software | K2: https://drive.google.com/file/d/1fzGMOVP8oCSnj7eaLmstMJs_p2Kp5jbl/view?usp=sharing | L2: Fashion retail faces high return rates from customers' uncertainty about online clothing fit, appearance, and styling, plus challenges trying multiple outfits in physical stores, causing financial losses for retailers and inconvenience for buyers. Vitron addresses this widespread issue with an AI-powered virtual try-on platform that realistically shows garments on users and provides personalized outfit recommendations based on body type and preferences, deployable as software for both online and offline retail without expensive hardware
A3: 2 | B3: Aathavan Valanarasu | C3: COMPLETED | D3: 19/07/25 | E3: 9342049639 | F3: {=_xlfn.XLOOKUP(I3,startify3.0!I:I,startify3.0!A:A)} -> 3 | G3: preinc | H3: yes | I3: SC-rea6ge | J3: AI / ML, SaaS, EdTech, Bio Tech | K3: https://drive.google.com/file/d/1icj55HRkpEE6D2YhMiuNvMZMm4qS83lU/view?usp=sharing | L3: Autism Spectrum Disorder (ASD) affects 1 in 100 children globally (WHO 2023), impacting over 70 million people worldwide and 10 million in India, with limited therapy access in rural areas due to high costs and scarce trained therapists, burdening individuals with ASD, caregivers, families, therapy centers, and schools. Niya Therapy Hub solves this through a VR-based AI-driven platform on Meta Quest headsets, featuring immersive therapy environments, an AI virtual guide for personalized support, real-time progress tracking, and skill-building modules that blend therapy, education, and engagement—making it portable, scalable, and collaborative unlike costly traditional sessions or non-immersive apps, targeting a $2 billion+ global therapy market.
A4: 3 | B4: Abinaya | C4: COMPLETED | E4: 9080721623 | F4: {=_xlfn.XLOOKUP(I4,startify3.0!I:I,startify3.0!A:A)} -> #N/A | I4: CEDAU-37 | J4: EdTech, Enviro Tech | K4: https://docs.google.com/presentation/d/1mFOPCn7ZHKzvNicJaWvacJD6nFsAMFeD/edit?usp=sharing&ouid=104277249549708518105&rtpof=true&sd=true | L4: SenseUs addresses a major gap in workplace training, where traditional LMS-based programs create awareness but fail to drive lasting behavioral change. Organizations struggle with recurring communication issues, low engagement, and ineffective culture-building because employees rarely get opportunities to practice real workplace situations. SenseUs solves this through a simulation-based training platform that places employees in interactive, decision-driven workplace scenarios with real-time responses, progressive difficulty, and behavior-focused gamification. By enabling continuous practice, reinforcement, and measurable learning outcomes, SenseUs helps embed empathy, respect, and responsible workplace behavior into organizational culture, creating safer, more inclusive, and productive work environments.
A5: 4 | B5: abishek A | C5: COMPLETED | E5: 8610961896 | F5: {=_xlfn.XLOOKUP(I5,startify3.0!I:I,startify3.0!A:A)} -> 80 | I5: sc-h83z6f | J5: AgriTech, CleanTech , IoT / Hardware, food Tech | K5: https://drive.google.com/file/d/15VC3YOTSvBp5zx_f2_UnedEDj7sMRjGc/view?usp=sharing | L5: Hydros addresses the global need for sustainable, local food in water-scarce, urban and peri-urban regions, where families and small farmers lack space, depend on chemical-intensive soil farming, and face rising demand for healthy produce without affordable, efficient technology. Hydros proposes a solar-powered, IoT-driven aquaponics system that combines fish and plants in a closed-loop unit using sensors, automated pumps, and aeration to maintain water and nutrient balance, reducing water use by up to 90%, eliminating chemical inputs, and enabling compact, scalable, low-maintenance farming for households, small farmers, and institutions
A6: 5 | B6: Akash | C6: COMPLETED | E6: 8754728402 | F6: {=_xlfn.XLOOKUP(I6,startify3.0!I:I,startify3.0!A:A)} -> #N/A | H6: yes | I6: CEDAU-34 | J6: Bio Tech , Enviro Tech | K6: https://docs.google.com/presentation/d/1vvNjk_1_mJJVLriLTt7MFXxwPhGuccHt/edit?usp=sharing&ouid=104277249549708518105&rtpof=true&sd=true | L6: India's 77+ million diabetes patients rely on painful finger-prick tests or expensive, bulky Continuous Glucose Monitors (CGMs) that are inaccessible to rural users, rigid, short-lived, and battery-dependent. The solution is a flexible, skin-conformal wearable patch using microporous carbon electrodes from upcycled PET waste, sesame stalks, and sewage sludge, enabling non-invasive sweat-based glucose sensing via enzyme layers and PVA hydrogel, with smartphone Bluetooth connectivity for real-time monitoring at 10x lower cost.
A7: 6 | B7: AKASH RS | C7: COMPLETED | E7: 7305494413 | F7: {=_xlfn.XLOOKUP(I7,startify3.0!I:I,startify3.0!A:A)} -> 227 | H7: yes | I7: SC-e4ss8o | J7: AI / ML, EdTech , Saas | K7: https://docs.google.com/presentation/d/1WbLTAapfRoC1Jw8AjPoUSNHbaO1Bni6Q/edit?usp=sharing&ouid=104277249549708518105&rtpof=true&sd=true | L7: ZapSkill by Veducate Skills & Technologies tackles engineering students' lack of hands-on practical learning despite industry demands for job-ready skills, with existing platforms being theoretical, non-interactive, and lacking real-time AI guidance or progress tracking. Colleges struggle with outdated labs and monitoring, hindering scalable industry-ready talent development. The solution delivers browser-based interactive missions with cloud-powered real-time practice environments an adaptive AI mentor for instant personalized feedback/hints, and AI-driven skill progression analytics to identify gaps, recommend micro-tasks, and certify internship readiness
A8: 7 | B8: Akshay Karthikeyan Sk | C8: COMPLETED | D8: 19/12/25 | E8: 9150452331 | F8: {=_xlfn.XLOOKUP(I8,startify3.0!I:I,startify3.0!A:A)} -> 182 | H8: yes | I8: SC-2us6k | J8: Fashion / Lifestyle, Enviro Tech | K8: https://drive.google.com/file/d/1iWc68HJJJgFSsLxllZe3TY45JOCKec0Z/view?usp=sharing | L8: Active individuals, professionals, and people in hot/humid/active environments experience discomfort and self-consciousness from body odor and fading clothing freshness throughout the day, as current apparel lacks lasting fragrance or odor control. Curio solves this through microencapsulation technology embedding fragrance microcapsules into fabric fibers during textile finishing for smart release via friction/heat/movement, delivering long-lasting freshness surviving 30-40 washes using eco-friendly non-toxic materials, offered as stylish affordable D2C apparel targeting Gen Z/millennials/active lifestyle adopters within India's $8.89B functional apparel market and $160.2M→$857.9M smart textiles niche (20.5% CAGR).
A9: 8 | B9: Alex | C9: COMPLETED | E9: 9500194696 | F9: {=_xlfn.XLOOKUP(I9,startify3.0!I:I,startify3.0!A:A)} -> 221 | H9: yes | I9: IPO-ojc1rs | J9: IoT / Hardware | K9: https://drive.google.com/file/d/1Ut3XYaHh13bLRoFmhbJoREBB6yk05q2M/view?usp=sharing | L9: Geosonic explores unsafe interactions between overhead and floor cranes in heavy equipment factories, where existing light-based anti-collision sensors are unreliable due to dust, lighting variations, maintenance difficulty, and blind spots, creating significant risk of collisions and accidents across dynamic crane operations. The solution is a scalable, low-cost ultrasonic sensor–based anti-collision system using custom microcontroller PCBs, a PLC-controlled sensing setup, MODBUS communication, and a handheld interface to ensure accurate distance detection, coordinated crane interlocking, and easier deployment across multiple crane systems
A10: 9 | B10: Anantha Kumar | C10: COMPLETED | D10: #N/A | E10: 7845471602 | I10: cedau-39 | J10: Fin Tech , App Development / Software | K10: https://drive.google.com/file/d/1zwrG0J_pCo6yZG42LAl7d5Jx_zdp-LZ_/view?usp=sharing | L10: Ztorys is a multi-language digital publishing platform that empowers writers to earn directly from their content without technical barriers or upfront costs. Addressing declining search traffic, high website setup expenses, and unstable monetization, Ztorys enables creators to publish in 340+ languages and earn through 55% ad revenue sharing, sponsored content, promotions, and affiliate commissions. With 110+ active writers, 250+ articles, and growing monthly engagement, the platform combines long-form articles and short “Notes” for virality and discovery. Targeting India’s 15 million writers and global creators, Ztorys aims to build a scalable, YouTube-like monetization ecosystem for written content
A11: 10 | B11: Anil Kumar | C11: COMPLETED | E11: 9705933771 | F11: {=_xlfn.XLOOKUP(I11,startify3.0!I:I,startify3.0!A:A)} -> 191 | H11: yes | I11: SC-os5t2w | J11: Consumables , Bio Tech, Sports Tech | K11: https://docs.google.com/presentation/d/1qyALgLmfBGwRQZVtXpNxFVOCOLST_2BK/edit?usp=sharing&ouid=104277249549708518105&rtpof=true&sd=true | L11: The problem is widespread chronic pain and muscle fatigue—affecting 1.5 billion people globally, 13% of adults in India, and 79% of people with joint pain—while current solutions like massage guns, heating pads, and TENS devices are bulky, stationary, or inconvenient, requiring active use or sticky pads. This under-served need exists within a rapidly growing global pain-management and sports recovery market worth tens of billions of dollars. The solution, SMARTHEAL, is a lightweight, wearable, washable massager combining heat, vibration, and TENS/EMS electrotherapy, delivering continuous, hands-free, app-controlled pain relief during daily activities.
A12: 11 | B12: Anjanarangarajan | C12: COMPLETED | D12: 45968 | E12: 9790339415 | F12: {=_xlfn.XLOOKUP(I12,startify3.0!I:I,startify3.0!A:A)} -> 52 | H12: yes | I12: SC-9au7v | J12: AI / ML, IoT / Hardware | K12: https://drive.google.com/file/d/1YWnN75jWtxNAdKR8L3b7q3YvrpJshX1-/view?usp=sharing | L12: NOVA AI addresses industrial hazards in chemical manufacturing MSMEs like those in Sivakasi, where manual monitoring fails to detect early gas leaks, thermal hotspots, and machine stress, leading to frequent fires, toxic exposures, and equipment failures. India reports 48,000+ factory accidents and 6,500+ fatalities (2017-2021), with Tamil Nadu among the top states and Sivakasi fireworks seeing 500+ fires, 300+ deaths over 10 years; 80% of factories lack real-time safety systems costing ₹50,000+ per node. The solution is an edge AI-powered multi-sensor system (thermal, gas, vibration, vision on Jetson Nano) for real-time hazard detection, automated shutdowns/ventilation, predictive maintenance, PPE compliance, and reports—all offline at ₹18-25k per modular node, 30-50% cheaper via local processing without cloud fees.
